Workbook

Sheet Basic Calcs Comparison
A2: Dimensions
C4: Units | D4: Version 1 | E4: Version 2 | F4: Version 3 | G4: ISS | H4: Notes | I4: Source
A5: Outer Diameter | B5: D1 | C5: m | D5: 100 | E5: 1000 | F5: 10000 | G5: 73 | H5: Inside diameter of the Seed Ring. ISS dimension relates to maximum length | I5: https://en.wikipedia.org/wiki/Electrical_system_of_the_International_Space_Station
A6: Section Outer Diameter | B6: d1 | C6: m | D6: 10 | E6: 100 | F6: 1000 | H6: Outside diamter of the section - for the purposes of simplicity assumed to be circular
A7: Inner Diameter | B7: D2 | C7: m | D7: =SUM(D5-(2*D6)) -> 80 | E7: =SUM(E5-(2*E6)) -> 800 | F7: =SUM(F5-(2*F6)) -> 8000
A8: Wall Thickness | B8: l1 | C8: m | D8: 0.02 | E8: 0.5 | F8: 10
A9: Section Area Outer | C9: m2 | D9: =SUM(3.1416/4*((D5*D5)-((D5-(2*D8))*(D5-(2*D8))))) -> 6.2819434 | E9: =SUM(3.1416/4*((E5*E5)-((E5-(2*E8))*(E5-(2*E8))))) -> 1570.0146 | F9: =SUM(3.1416/4*((F5*F5)-((F5-(2*F8))*(F5-(2*F8))))) -> 313845.84 | H9: Area of the outer walls required to be fully covered by the print head
A10: Section Area Ground Floor | C10: m2 | D10: =(D5-(D8*2))*D8 -> 1.9992 | E10: =(E5-(E8*2))*E8 -> 499.5 | F10: =(F5-(F8*2))*F8 -> 99800 | H10: Area of the central floor area required to be fully covered by the print head
A11: Additional Print Area | C11: % | D11: 2 | E11: 2 | F11: 40 | H11: For further inner floors / walls as a percentage of the central floor section area
A12: Total Sectional Area | C12: m2 | D12: =D9+D10+(D10*D11) -> 12.279543 | E12: =E9+E10+(E10*E11) -> 3068.5146 | F12: =F9+F10+(F10*F11) -> 4405645.8 | H12: This number is used in conjunction with the print nozzle size and print depth to calculate how many revolutions are required to cover the area
A13: Outer Torus Volume | B13: V1 | C13: m3 | D13: =SUM(3.1416*3.1416)*(D5/2+D7/2)*(D5/2-D7/2)*(D5/2-D7/2)/4 -> 22206.714 | E13: =SUM(3.1416*3.1416)*(E5/2+E7/2)*(E5/2-E7/2)*(E5/2-E7/2)/4 -> 22206714 | F13: =SUM(3.1416*3.1416)*(F5/2+F7/2)*(F5/2-F7/2)*(F5/2-F7/2)/4 -> 2.2206714e+10
A14: Inside Torus Outer Diameter | C14: m | D14: =D5-(D8*2) -> 99.96 | E14: =E5-(E8*2) -> 999 | F14: =F5-(F8*2) -> 9980
A15: Inside Torus Inner Diameter | C15: m | D15: =D7+(D8*2) -> 80.04 | E15: =E7+(E8*2) -> 801 | F15: =F7+(F8*2) -> 8020
A16: Inside Torus Volume | C16: m3 | D16: =SUM(3.1416*3.1416)*(D14/2+D15/2)*(D14/2-D15/2)*(D14/2-D15/2)/4 -> 22029.415 | E16: =SUM(3.1416*3.1416)*(E14/2+E15/2)*(E14/2-E15/2)*(E14/2-E15/2)/4 -> 21764800 | F16: =SUM(3.1416*3.1416)*(F14/2+F15/2)*(F14/2-F15/2)*(F14/2-F15/2)/4 -> 2.1327328e+10 | H16: Layer thickness
A17: Torus Shell Volume | C17: m3 | D17: =SUM(D13-D16) -> 177.2984 | E17: =SUM(E13-E16) -> 441913.6 | F17: =SUM(F13-F16) -> 8.7938586e+08
A18: Central floor Volume | C18: m3 | D18: =(3.1416*D8*D14*(D6-2*D8)) -> 62.55564 | E18: =(3.1416*E8*E14*(E6-2*E8)) -> 155353.69 | F18: =(3.1416*F8*F14*(F6-2*F8)) -> 3.0726105e+08 | H18: Volume associated with a ring shaped floor at the widest point wih a thickness equal to the outer wall
A19: Additional Print Volume | C19: m3 | D19: =SUM(D11*D18)+D18 -> 187.66692 | E19: =SUM(E11*E18)+E18 -> 466061.07 | F19: =SUM(F11*F18)+F18 -> 1.2597703e+10
A20: Internal Volume | C20: m3 | D20: =D16-D19 -> 21841.748 | E20: =E16-E19 -> 21298739 | F20: =F16-F19 -> 8.729625e+09 | G20: 932 | I20: https://www.nasa.gov/feature/facts-and-figures
A21: Internal Volume | C21: km3 | D21: =D20/1000000000 -> 2.1841748e-05 | E21: =E20/1000000000 -> 0.021298739 | F21: =F20/1000000000 -> 8.729625
A22: Total Print Volume | C22: m3 | D22: =D17+D19 -> 364.96532 | E22: =E17+E19 -> 907974.68 | F22: =F17+F19 -> 1.3477089e+10
A23: Total Print Volume | C23: km3 | D23: =D22/1000000000 -> 3.6496532e-07 | E23: =E22/1000000000 -> 0.00090797468 | F23: =F22/1000000000 -> 13.477089
A24: People on Board | D24: 50 | E24: 10000 | F24: 100000000 | G24: 6
A25: Ground Floor Space | C25: m2 | D25: =3.1416*2*(D5-D7)*D6 -> 1256.64 | E25: =3.1416*2*(E5-E7)*E6 -> 125664 | F25: =3.1416*2*(F5-F7)*F6 -> 12566400
A26: Ground Floor Space | C26: km2 | D26: =D25/1000000 -> 0.00125664 | E26: =E25/1000000 -> 0.125664 | F26: =F25/1000000 -> 12.5664
A27: Average volume per person | C27: m3 | D27: =D20/D24/2 -> 218.41748 | E27: =E20/E24/2 -> 1064.937 | F27: =F20/F24/2 -> 43.648125 | G27: =SUM(G20/G24) -> 155.33333 | H27: Approximate calculation assumes 50% of volume unusable
A28: Floor Space per person at 2.5 m ceiling | C28: m2 | D28: =D27/2.5 -> 87.366994 | E28: =E27/2.5 -> 425.97478 | F28: =F27/2.5 -> 17.45925 | H28: Approximate calculation does not consider curvature of structure. Assumes 2.5m room heights
A29: Total Mass of People | C29: Ton | D29: =SUM(D24*62)/1000 -> 3.1 | E29: =SUM(E24*62)/1000 -> 620 | F29: =SUM(F24*62)/1000 -> 6200000 | H29: Excluding personal Possessions | I29: https://en.wikipedia.org/wiki/Human_body_weight
A31: Manufacturing Process
A33: Print Speed | C33: m/s | D33: 0.5 | E33: 1 | F33: 8 | H33: How fast the printer head moves relative to the surface being printed Current home 3D print speed. Aluminium extrusion in range of 5 - 50 m/min (0.08 - 0.8 m/s)
A34: Nozzle Diameter | C34: mm | D34: 4 | E34: 100 | F34: 1000
A35: Print Depth | C35: mm | D35: 2 | E35: 20 | F35: 250
A36: Nozzle volumetric flow rate | C36: cm3/s | D36: =SUM(D34*D33*D35) -> 4 | E36: =SUM(E34*E33*E35) -> 2000 | F36: =SUM(F34*F33*F35) -> 2000000 | H36: For all Nozzles
A37: Rotational Speed | C37: RPM | D37: =D33*60/(3.1416*D5) -> 0.095492743 | E37: =E33*60/(3.1416*E5) -> 0.019098549 | F37: =F33*60/(3.1416*F5) -> 0.015278839 | H37: Calculated from the print head speed at the outer diameter
A38: G-force outer edge (RCF) | D38: =D37*D37*1.118*0.001*(D5/2) -> 0.00050974449 | E38: =E37*E37*1.118*0.001*(E5/2) -> 0.0002038978 | F38: =F37*F37*1.118*0.001*(F5/2) -> 0.0013049459 | H38: Induced by rotation of ring
A39: Number of Print Head Nozzles | D39: 4 | E39: 16 | F39: 100 | H39: Number of nozzles for the main construction material - separate print head are assumed for other materials
A40: Flow Rate per Nozzles | C40: kg/s | D40: =D41/D39 -> 0.01082 | E40: =E41/E39 -> 5.68 | F40: =F41/F39 -> 5680
A41: Flow Rate All Nozzles | C41: kg/s | D41: =SUM(D36*D51*D39)/1000000 -> 0.04328 | E41: =SUM(E36*E51*E39)/1000000 -> 90.88 | F41: =SUM(F36*F51*F39)/1000000 -> 568000 | H41: Used in power sonsumption calculations
A42: Flow Rate All Nozzles | C42: Ton/s | D42: =D41/1000 -> 4.328e-05 | E42: =E41/1000 -> 0.09088 | F42: =F41/1000 -> 568
A43: Print Efficiency | C43: % | D43: 0.9 | E43: 0.9 | F43: 0.9 | H43: Tme Printing vs Time Not Printing NOT INCLUDING wall design desity
A44: Number of Complete Revolutions | C44: million | D44: =D12/(D34*D35/1000)/1000 -> 1.5349429 | E44: =E12/(E34*E35/1000)/1000 -> 1.5342573 | F44: =F12/(F34*F35/1000)/1000 -> 17.622583 | H44: Based upon the total sectional area divided by the print area (nozzle diameter x print depth x number of nozzles)
...

Sheet gravity chart
A2: Dimensions
C4: Version 1 | D4: Version 2 | E4: Version 3 | F4: Version 3 | G4: Version 4 | H4: Version 5 | I4: Version 6 | J4: Version 7 | K4: Version 8 | L4: Version 9 | M4: Version 10 | N4: Version 11 | O4: Units
A5: Outer Diameter | B5: D1 | C5: 100 | D5: 1000 | E5: 2000 | F5: 4000 | G5: 6000 | H5: 8000 | I5: 10000 | J5: 20000 | K5: 40000 | L5: 60000 | M5: 80000 | N5: 100000 | O5: m
A6: Section Outer Diameter | B6: d1 | C6: 10 | D6: 100 | E6: 100 | F6: 10000 | G6: 10000 | H6: 10000 | I6: 10000 | J6: 10000 | K6: 10000 | L6: 10000 | M6: 10000 | N6: 10000 | O6: m
A7: Inner Diameter | B7: D2 | C7: =SUM(C5-(2*C6)) -> 80 | D7: =SUM(D5-(2*D6)) -> 800 | E7: =SUM(E5-(2*E6)) -> 1800 | F7: =SUM(F5-(2*F6)) -> -16000 | G7: =SUM(G5-(2*G6)) -> -14000 | H7: =SUM(H5-(2*H6)) -> -12000 | I7: =SUM(I5-(2*I6)) -> -10000 | J7: =SUM(J5-(2*J6)) -> 0 | ... N7: =SUM(N5-(2*N6)) -> 80000 | O7: m
A8: Wall Thickness | B8: l1 | C8: 0.02 | D8: 0.5 | E8: 1.5 | F8: 10 | G8: 11 | H8: 12 | I8: 13 | J8: 14 | K8: 15 | L8: 16 | M8: 17 | N8: 18 | O8: m
A9: Section Area Outer | C9: =SUM(3.1416/4*((C5*C5)-((C5-(2*C8))*(C5-(2*C8))))) -> 6.2819434 | D9: =SUM(3.1416/4*((D5*D5)-((D5-(2*D8))*(D5-(2*D8))))) -> 1570.0146 | E9: =SUM(3.1416/4*((E5*E5)-((E5-(2*E8))*(E5-(2*E8))))) -> 9417.7314 | F9: =SUM(3.1416/4*((F5*F5)-((F5-(2*F8))*(F5-(2*F8))))) -> 125349.84 | G9: =SUM(3.1416/4*((G5*G5)-((G5-(2*G8))*(G5-(2*G8))))) -> 206965.47 | H9: =SUM(3.1416/4*((H5*H5)-((H5-(2*H8))*(H5-(2*H8))))) -> 301141.21 | I9: =SUM(3.1416/4*((I5*I5)-((I5-(2*I8))*(I5-(2*I8))))) -> 407877.07 | J9: =SUM(3.1416/4*((J5*J5)-((J5-(2*J8))*(J5-(2*J8))))) -> 879032.25 | ... N9: =SUM(3.1416/4*((N5*N5)-((N5-(2*N8))*(N5-(2*N8))))) -> 5653862.1 | O9: m2
A10: Section Area Ground Floor | C10: =(C5-(C8*2))*C8 -> 1.9992 | D10: =(D5-(D8*2))*D8 -> 499.5 | E10: =(E5-(E8*2))*E8 -> 2995.5 | F10: =(F5-(F8*2))*F8 -> 39800 | G10: =(G5-(G8*2))*G8 -> 65758 | H10: =(H5-(H8*2))*H8 -> 95712 | I10: =(I5-(I8*2))*I8 -> 129662 | J10: =(J5-(J8*2))*J8 -> 279608 | ... N10: =(N5-(N8*2))*N8 -> 1799352 | O10: m2
A11: Additional Print Area | C11: 2 | D11: 2 | E11: 3 | F11: 40 | G11: 41 | H11: 42 | I11: 43 | J11: 44 | K11: 45 | L11: 46 | M11: 47 | N11: 48 | O11: %
A12: Total Sectional Area | C12: =C9+C10+(C10*C11) -> 12.279543 | D12: =D9+D10+(D10*D11) -> 3068.5146 | E12: =E9+E10+(E10*E11) -> 21399.731 | F12: =F9+F10+(F10*F11) -> 1757149.8 | G12: =G9+G10+(G10*G11) -> 2968801.5 | H12: =H9+H10+(H10*H11) -> 4416757.2 | I12: =I9+I10+(I10*I11) -> 6113005.1 | J12: =J9+J10+(J10*J11) -> 13461392 | ... N12: =N9+N10+(N10*N11) -> 93822110 | O12: m2
A13: Outer Torus Volume | B13: V1 | C13: =SUM(3.1416*3.1416)*(C5/2+C7/2)*(C5/2-C7/2)*(C5/2-C7/2)/4 -> 22206.714 | D13: =SUM(3.1416*3.1416)*(D5/2+D7/2)*(D5/2-D7/2)*(D5/2-D7/2)/4 -> 22206714 | E13: =SUM(3.1416*3.1416)*(E5/2+E7/2)*(E5/2-E7/2)*(E5/2-E7/2)/4 -> 46880840 | F13: =SUM(3.1416*3.1416)*(F5/2+F7/2)*(F5/2-F7/2)*(F5/2-F7/2)/4 -> -1480447584000 | G13: =SUM(3.1416*3.1416)*(G5/2+G7/2)*(G5/2-G7/2)*(G5/2-G7/2)/4 -> -986965056000 | H13: =SUM(3.1416*3.1416)*(H5/2+H7/2)*(H5/2-H7/2)*(H5/2-H7/2)/4 -> -493482528000 | I13: =SUM(3.1416*3.1416)*(I5/2+I7/2)*(I5/2-I7/2)*(I5/2-I7/2)/4 -> 0 | J13: =SUM(3.1416*3.1416)*(J5/2+J7/2)*(J5/2-J7/2)*(J5/2-J7/2)/4 -> 2467412640000 | ... N13: =SUM(3.1416*3.1416)*(N5/2+N7/2)*(N5/2-N7/2)*(N5/2-N7/2)/4 -> 22206713760000 | O13: m3
A14: Inside Torus Outer Diameter | C14: =C5-(C8*2) -> 99.96 | D14: =D5-(D8*2) -> 999 | E14: =E5-(E8*2) -> 1997 | F14: =F5-(F8*2) -> 3980 | G14: =G5-(G8*2) -> 5978 | H14: =H5-(H8*2) -> 7976 | I14: =I5-(I8*2) -> 9974 | J14: =J5-(J8*2) -> 19972 | ... N14: =N5-(N8*2) -> 99964 | O14: m
A15: Inside Torus Inner Diameter | C15: =C7+(C8*2) -> 80.04 | D15: =D7+(D8*2) -> 801 | E15: =E7+(E8*2) -> 1803 | F15: =F7+(F8*2) -> -15980 | G15: =G7+(G8*2) -> -13978 | H15: =H7+(H8*2) -> -11976 | I15: =I7+(I8*2) -> -9974 | J15: =J7+(J8*2) -> 28 | ... N15: =N7+(N8*2) -> 80036 | O15: m
A16: Inside Torus Volume | C16: =SUM(3.1416*3.1416)*(C14/2+C15/2)*(C14/2-C15/2)*(C14/2-C15/2)/4 -> 22029.415 | D16: =SUM(3.1416*3.1416)*(D14/2+D15/2)*(D14/2-D15/2)*(D14/2-D15/2)/4 -> 21764800 | E16: =SUM(3.1416*3.1416)*(E14/2+E15/2)*(E14/2-E15/2)*(E14/2-E15/2)/4 -> 44110183 | F16: =SUM(3.1416*3.1416)*(F14/2+F15/2)*(F14/2-F15/2)*(F14/2-F15/2)/4 -> -1.4745317e+12 | G16: =SUM(3.1416*3.1416)*(G14/2+G15/2)*(G14/2-G15/2)*(G14/2-G15/2)/4 -> -9.8262719e+11 | H16: =SUM(3.1416*3.1416)*(H14/2+H15/2)*(H14/2-H15/2)*(H14/2-H15/2)/4 -> -4.9111665e+11 | I16: =SUM(3.1416*3.1416)*(I14/2+I15/2)*(I14/2-I15/2)*(I14/2-I15/2)/4 -> 0 | J16: =SUM(3.1416*3.1416)*(J14/2+J15/2)*(J14/2-J15/2)*(J14/2-J15/2)/4 -> 2.4536145e+12 | ... N16: =SUM(3.1416*3.1416)*(N14/2+N15/2)*(N14/2-N15/2)*(N14/2-N15/2)/4 -> 2.2047113e+13 | O16: m3
A17: Torus Shell Volume | C17: =SUM(C13-C16) -> 177.2984 | D17: =SUM(D13-D16) -> 441913.6 | E17: =SUM(E13-E16) -> 2770657.7 | F17: =SUM(F13-F16) -> -5.9158685e+09 | G17: =SUM(G13-G16) -> -4.3378693e+09 | H17: =SUM(H13-H16) -> -2.3658737e+09 | I17: =SUM(I13-I16) -> 0 | J17: =SUM(J13-J16) -> 1.3798166e+10 | ... N17: =SUM(N13-N16) -> 1.5960054e+11 | O17: m3
A18: Central floor Volume | C18: =(3.1416*C8*C14*(C6-2*C8)) -> 62.55564 | D18: =(3.1416*D8*D14*(D6-2*D8)) -> 155353.69 | E18: =(3.1416*E8*E14*(E6-2*E8)) -> 912834.29 | F18: =(3.1416*F8*F14*(F6-2*F8)) -> 1.2478561e+09 | G18: =(3.1416*G8*G14*(G6-2*G8)) -> 2.0613085e+09 | H18: =(3.1416*H8*H14*(H6-2*H8)) -> 2.9996717e+09 | I18: =(3.1416*I8*I14*(I6-2*I8)) -> 4.0628704e+09 | J18: =(3.1416*J8*J14*(J6-2*J8)) -> 8.7595693e+09 | ... N18: =(3.1416*N8*N14*(N6-2*N8)) -> 5.632494e+10 | O18: m3
A19: Additional Print Volume | C19: =SUM(C11*C18)+C18 -> 187.66692 | D19: =SUM(D11*D18)+D18 -> 466061.07 | E19: =SUM(E11*E18)+E18 -> 3651337.2 | F19: =SUM(F11*F18)+F18 -> 5.11621e+10 | G19: =SUM(G11*G18)+G18 -> 8.6574955e+10 | H19: =SUM(H11*H18)+H18 -> 1.2898588e+11 | I19: =SUM(I11*I18)+I18 -> 1.787663e+11 | J19: =SUM(J11*J18)+J18 -> 3.9418062e+11 | ... N19: =SUM(N11*N18)+N18 -> 2.7599221e+12 | O19: m3
A20: Internal Volume | C20: =C16-C19 -> 21841.748 | D20: =D16-D19 -> 21298739 | E20: =E16-E19 -> 40458845 | F20: =F16-F19 -> -1.5256938e+12 | G20: =G16-G19 -> -1.0692021e+12 | H20: =H16-H19 -> -6.2010254e+11 | I20: =I16-I19 -> -1.787663e+11 | J20: =J16-J19 -> 2.0594339e+12 | ... N20: =N16-N19 -> 1.9287191e+13 | O20: m3
A21: Internal Volume | C21: =C20/1000000000 -> 2.1841748e-05 | D21: =D20/1000000000 -> 0.021298739 | E21: =E20/1000000000 -> 0.040458845 | F21: =F20/1000000000 -> -1525.6938 | G21: =G20/1000000000 -> -1069.2021 | H21: =H20/1000000000 -> -620.10254 | I21: =I20/1000000000 -> -178.7663 | J21: =J20/1000000000 -> 2059.4339 | ... N21: =N20/1000000000 -> 19287.191 | O21: km3
A22: Total Print Volume | C22: =C17+C19 -> 364.96532 | D22: =D17+D19 -> 907974.68 | E22: =E17+E19 -> 6421994.8 | F22: =F17+F19 -> 4.5246231e+10 | G22: =G17+G19 -> 8.2237086e+10 | H22: =H17+H19 -> 1.2662001e+11 | I22: =I17+I19 -> 1.787663e+11 | J22: =J17+J19 -> 4.0797878e+11 | ... N22: =N17+N19 -> 2.9195226e+12 | O22: m3
A23: Total Print Volume | C23: =C22/1000000000 -> 3.6496532e-07 | D23: =D22/1000000000 -> 0.00090797468 | E23: =E22/1000000000 -> 0.0064219948 | F23: =F22/1000000000 -> 45.246231 | G23: =G22/1000000000 -> 82.237086 | H23: =H22/1000000000 -> 126.62001 | I23: =I22/1000000000 -> 178.7663 | J23: =J22/1000000000 -> 407.97878 | ... N23: =N22/1000000000 -> 2919.5226 | O23: km3
A24: People on Board | C24: 50 | D24: 10000 | E24: 10001 | F24: 100000000 | G24: 100000001 | H24: 100000002 | I24: 100000003 | J24: 100000004 | K24: 100000005 | L24: 100000006 | M24: 100000007 | N24: 100000008
A25: Ground Floor Space | C25: =3.1416*2*(C5-C7)*C6 -> 1256.64 | D25: =3.1416*2*(D5-D7)*D6 -> 125664 | E25: =3.1416*2*(E5-E7)*E6 -> 125664 | F25: =3.1416*2*(F5-F7)*F6 -> 1256640000 | G25: =3.1416*2*(G5-G7)*G6 -> 1256640000 | H25: =3.1416*2*(H5-H7)*H6 -> 1256640000 | I25: =3.1416*2*(I5-I7)*I6 -> 1256640000 | J25: =3.1416*2*(J5-J7)*J6 -> 1256640000 | ... N25: =3.1416*2*(N5-N7)*N6 -> 1256640000 | O25: m2
A26: Ground Floor Space | C26: =C25/1000000 -> 0.00125664 | D26: =D25/1000000 -> 0.125664 | E26: =E25/1000000 -> 0.125664 | F26: =F25/1000000 -> 1256.64 | G26: =G25/1000000 -> 1256.64 | H26: =H25/1000000 -> 1256.64 | I26: =I25/1000000 -> 1256.64 | J26: =J25/1000000 -> 1256.64 | ... N26: =N25/1000000 -> 1256.64 | O26: km2
A27: Average volume per person | C27: =C20/C24/2 -> 218.41748 | D27: =D20/D24/2 -> 1064.937 | E27: =E20/E24/2 -> 2022.74 | F27: =F20/F24/2 -> -7628.4691 | G27: =G20/G24/2 -> -5346.0107 | H27: =H20/H24/2 -> -3100.5126 | I27: =I20/I24/2 -> -893.83146 | J27: =J20/J24/2 -> 10297.169 | ... N27: =N20/N24/2 -> 96435.948 | O27: m3
A28: Floor Space per person at 2.5 m ceiling | C28: =C27/2.5 -> 87.366994 | D28: =D27/2.5 -> 425.97478 | E28: =E27/2.5 -> 809.096 | F28: =F27/2.5 -> -3051.3876 | G28: =G27/2.5 -> -2138.4043 | H28: =H27/2.5 -> -1240.205 | I28: =I27/2.5 -> -357.53258 | J28: =J27/2.5 -> 4118.8675 | ... N28: =N27/2.5 -> 38574.379 | O28: m2
A29: Total Mass of People | C29: =SUM(C24*62)/1000 -> 3.1 | D29: =SUM(D24*62)/1000 -> 620 | E29: =SUM(E24*62)/1000 -> 620.062 | F29: =SUM(F24*62)/1000 -> 6200000 | G29: =SUM(G24*62)/1000 -> 6200000.1 | H29: =SUM(H24*62)/1000 -> 6200000.1 | I29: =SUM(I24*62)/1000 -> 6200000.2 | J29: =SUM(J24*62)/1000 -> 6200000.2 | ... N29: =SUM(N24*62)/1000 -> 6200000.5 | O29: Ton
A31: Manufacturing Process
A33: Print Speed | C33: 15.5 | D33: 50 | E33: 70 | F33: 100 | G33: 122 | H33: 140 | I33: 157 | J33: 222 | K33: 315 | L33: 382 | M33: 445 | N33: 495 | O33: m/s
A34: Nozzle Diameter | C34: 4 | D34: 100 | E34: 100 | F34: 2000 | G34: 2000 | H34: 2000 | I34: 2000 | J34: 2000 | K34: 2000 | L34: 2000 | M34: 2000 | N34: 2000 | O34: mm
A35: Print Depth | C35: 2 | D35: 20 | E35: 20 | F35: 1000 | G35: 1000 | H35: 1000 | I35: 1000 | J35: 1000 | K35: 1000 | L35: 1000 | M35: 1000 | N35: 1000 | O35: mm
A36: Nozzle volumetric flow rate | C36: =SUM(C34*C33*C35) -> 124 | D36: =SUM(D34*D33*D35) -> 100000 | E36: =SUM(E34*E33*E35) -> 140000 | F36: =SUM(F34*F33*F35) -> 200000000 | G36: =SUM(G34*G33*G35) -> 244000000 | H36: =SUM(H34*H33*H35) -> 280000000 | I36: =SUM(I34*I33*I35) -> 314000000 | J36: =SUM(J34*J33*J35) -> 444000000 | ... N36: =SUM(N34*N33*N35) -> 990000000 | O36: cm3/s
A37: Rotational Speed | C37: =C33*60/(3.1416*C5) -> 2.960275 | D37: =D33*60/(3.1416*D5) -> 0.95492743 | E37: =E33*60/(3.1416*E5) -> 0.6684492 | F37: =F33*60/(3.1416*F5) -> 0.47746371 | G37: =G33*60/(3.1416*G5) -> 0.38833715 | H37: =H33*60/(3.1416*H5) -> 0.3342246 | I37: =I33*60/(3.1416*I5) -> 0.29984721 | J37: =J33*60/(3.1416*J5) -> 0.21199389 | ... N37: =N33*60/(3.1416*N5) -> 0.094537815 | O37: RPM
A38: G-force outer edge (RCF) | C38: =C37*C37*1.118*0.001*(C5/2) -> 0.48986446 | D38: =D37*D37*1.118*0.001*(D5/2) -> 0.50974449 | E38: =E37*E37*1.118*0.001*(E5/2) -> 0.4995496 | F38: =F37*F37*1.118*0.001*(F5/2) -> 0.50974449 | G38: =G37*G37*1.118*0.001*(G5/2) -> 0.50580247 | H38: =H37*H37*1.118*0.001*(H5/2) -> 0.4995496 | I38: =I37*I37*1.118*0.001*(I5/2) -> 0.50258768 | J38: =J37*J37*1.118*0.001*(J5/2) -> 0.50244495 | ... N38: =N37*N37*1.118*0.001*(N5/2) -> 0.49960058
A39: Number of Print Head Nozzles | C39: 4 | D39: 16 | F39: 1000 | G39: 1001 | H39: 1002 | I39: 1003 | J39: 1004 | K39: 1005 | L39: 1006 | M39: 1007 | N39: 1008
A40: Flow Rate per Nozzles | C40: =C41/C39 -> 0.33542 | D40: =D41/D39 -> 284 | F40: =F41/F39 -> 568000 | G40: =G41/G39 -> 0 | H40: =H41/H39 -> 0 | I40: =I41/I39 -> 0 | J40: =J41/J39 -> 255300 | K40: =K41/K39 -> 94500 | L40: =L41/L39 -> 114600 | M40: =M41/M39 -> 0 | N40: =N41/N39 -> 0
A41: Flow Rate All Nozzles | C41: =SUM(C36*C51*C39)/1000000 -> 1.34168 | D41: =SUM(D36*D51*D39)/1000000 -> 4544 | F41: =SUM(F36*F51*F39)/1000000 -> 568000000 | G41: =SUM(G36*G51*G39)/1000000 -> 0 | H41: =SUM(H36*H51*H39)/1000000 -> 0 | I41: =SUM(I36*I51*I39)/1000000 -> 0 | J41: =SUM(J36*J51*J39)/1000000 -> 256321200 | K41: =SUM(K36*K51*K39)/1000000 -> 94972500 | L41: =SUM(L36*L51*L39)/1000000 -> 115287600 | M41: =SUM(M36*M51*M39)/1000000 -> 0 | N41: =SUM(N36*N51*N39)/1000000 -> 0
A42: Flow Rate All Nozzles | C42: =C41/1000 -> 0.00134168 | D42: =D41/1000 -> 4.544 | F42: =F41/1000 -> 568000 | G42: =G41/1000 -> 0 | H42: =H41/1000 -> 0 | I42: =I41/1000 -> 0 | J42: =J41/1000 -> 256321.2 | K42: =K41/1000 -> 94972.5 | L42: =L41/1000 -> 115287.6 | M42: =M41/1000 -> 0 | N42: =N41/1000 -> 0
A43: Print Efficiency | C43: 0.9 | D43: 0.9 | F43: 0.9 | G43: 1.9 | H43: 2.9 | I43: 3.9 | J43: 4.9 | K43: 5.9 | L43: 6.9 | M43: 7.9 | N43: 8.9
A44: Number of Complete Revolutions | C44: =C12/(C34*C35/1000)/1000 -> 1.5349429 | D44: =D12/(D34*D35/1000)/1000 -> 1.5342573 | F44: =F12/(F34*F35/1000)/1000 -> 0.87857492 | G44: =G12/(G34*G35/1000)/1000 -> 1.4844007 | H44: =H12/(H34*H35/1000)/1000 -> 2.2083786 | I44: =I12/(I34*I35/1000)/1000 -> 3.0565025 | J44: =J12/(J34*J35/1000)/1000 -> 6.7306961 | K44: =K12/(K34*K35/1000)/1000 -> 14.731777 | L44: =L12/(L34*L35/1000)/1000 -> 24.055534 | M44: =M12/(M34*M35/1000)/1000 -> 34.761962 | N44: =N12/(N34*N35/1000)/1000 -> 46.911055
...

Sheet Sheet7
B2: 100 | C2: 23
B3: 1000 | C3: 70
B4: 100000 | C4: 700

Sheet Chart Comparison
B1: Version 1 | C1: Version 2 | D1: Version 3 | H1: Version 1 | I1: Version 2 | J1: Version 3
A2: Wall Thickness | B2: ='Basic Calcs Comparison'!D8*100 -> 2 | C2: ='Basic Calcs Comparison'!E8*100 -> 50 | D2: ='Basic Calcs Comparison'!F8*100 -> 1000 | E2: cm | G2: Wall Thickness | H2: 2 | I2: 5 | J2: 10
A3: Print Time | B3: ='Basic Calcs Comparison'!D46 -> 8.4950122 | C3: ='Basic Calcs Comparison'!E46 -> 10.614022 | D3: ='Basic Calcs Comparison'!F46 -> 24.382675 | E3: years | G3: Print Time | H3: 1.0791824 | I3: 2.6836218 | J3: 5.3195182
A5: Wall Thickness | B5: =B2 -> 2 | C5: =C2 -> 50 | D5: =D2 -> 1000
A6: Falcon Heavy Lifts | B6: ='Basic Calcs Comparison'!D56 -> 7.7127437 | C6: ='Basic Calcs Comparison'!E56 -> 40291.376 | D6: ='Basic Calcs Comparison'!F56 -> 2.9902291e+08
A8: Total Print Volume | B8: ='Basic Calcs Comparison'!D22 -> 364.96532 | C8: ='Basic Calcs Comparison'!E22 -> 907974.68 | D8: ='Basic Calcs Comparison'!F22 -> 1.3477089e+10 | E8: m3
A9: People on Board | B9: ='Basic Calcs Comparison'!D24 -> 50 | C9: ='Basic Calcs Comparison'!E24 -> 10000 | D9: ='Basic Calcs Comparison'!F24 -> 100000000
A10: Average volume per person | B10: ='Basic Calcs Comparison'!D27 -> 218.41748 | C10: ='Basic Calcs Comparison'!E27 -> 1064.937 | D10: ='Basic Calcs Comparison'!F27 -> 43.648125 | E10: m3
A11: Total Mass | B11: ='Basic Calcs Comparison'!D53 -> 493.6156 | C11: ='Basic Calcs Comparison'!E53 -> 2578648.1 | D11: ='Basic Calcs Comparison'!F53 -> 1.9137466e+10 | E11: Tonnes
A13: Lifts frequency | B13: ='Basic Calcs Comparison'!D58 -> 402.02029 | C13: ='Basic Calcs Comparison'!E58 -> 0.096152538 | D13: ='Basic Calcs Comparison'!F58 -> 2.9762524e-05 | E13: days
A15: Continuous Power | B15: ='Basic Calcs Comparison'!D66 -> 127.98514 | C15: ='Basic Calcs Comparison'!E66 -> 70107.429 | D15: ='Basic Calcs Comparison'!F66 -> 4.3817143e+08 | E15: kW
A16: Theroretical Minimum Panel Size | B16: ='Basic Calcs Comparison'!D69 -> 234.40502 | C16: ='Basic Calcs Comparison'!E69 -> 128401.88 | D16: ='Basic Calcs Comparison'!F69 -> 8.0251177e+08 | E16: m2

Sheet Materials Properties
E1: 1 | F1: 2 | G1: 3 | H1: Material | I1: Density kg/m3 | J1: Notes / Source | N1: Melt Energy kWhrs/ton | O1: Notes / Source
A2: 1 | B2: 2 | C2: 1 | D2: 1 | E2: =IF(B2=A2,I2,"") | F2: =IF(C2=A2,I2,"") -> 2840 | G2: =IF(D2=A2,I2,"") -> 2840 | H2: Moon Rock | I2: 2840 | J2: http://www.psrd.hawaii.edu/CosmoSparks/July12/Lunar-rock-densities.html | K2: =IF(A2=B2,N2,"") | L2: =IF(C2=A2,N2,"") -> 150 | M2: =IF(D2=A2,N2,"") -> 150 | N2: 150 | O2: Assumed to be that of substrate material. Estimate only
A3: 2 | B3: =B2 -> 2 | C3: =C2 -> 1 | D3: =D2 -> 1 | E3: =IF(B3=A3,I3,"") -> 2705 | F3: =IF(C3=A3,I3,"") | G3: =IF(D3=A3,I3,"") | H3: Auminium | I3: 2705 | J3: https://theengineeringmindset.com/density-of-metals/ | K3: =IF(A3=B3,N3,"") -> 575 | L3: =IF(C3=A3,N3,"") | M3: =IF(D3=A3,N3,"") | N3: 575 | O3: https://electroheatinduction.com/how-to-calculate-electricity-cost-for-melting-metal-in-induction-melting-furnace/
A4: 3 | B4: =B3 -> 2 | C4: =C3 -> 1 | D4: =D3 -> 1 | E4: =IF(B4=A4,I4,"") | F4: =IF(C4=A4,I4,"") | G4: =IF(D4=A4,I4,"") | H4: Steel | I4: 7850 | J4: https://theengineeringmindset.com/density-of-metals/ | K4: =IF(A4=B4,N4,"") | L4: =IF(C4=A4,N4,"") | M4: =IF(D4=A4,N4,"") | N4: 600 | O4: https://electroheatinduction.com/how-to-calculate-electricity-cost-for-melting-metal-in-induction-melting-furnace/
A5: 4 | B5: =B4 -> 2 | C5: =C4 -> 1 | D5: =D4 -> 1 | E5: =IF(B5=A5,I5,"") | F5: =IF(C5=A5,I5,"") | G5: =IF(D5=A5,I5,"") | H5: High Impact ABS | I5: 1100 | J5: https://omnexus.specialchem.com/polymer-properties/properties/density | K5: =IF(A5=B5,N5,"") | L5: =IF(C5=A5,N5,"") | M5: =IF(D5=A5,N5,"") | N5: =0.00029307*342*1000 -> 100.22994 | O5: https://www.ptonline.com/articles/injection-molding-#:~:text=A%20kilogram%20of%20a%20semi-crystalline%20resin%2C%20such%20as,vs.%20342%29%2C%20yet%20their%20processing%20temperatures%20are%20similar.
A6: 5 | B6: =B5 -> 2 | C6: =C5 -> 1 | D6: =D5 -> 1 | E6: =IF(B6=A6,I6,"") | F6: =IF(C6=A6,I6,"") | G6: =IF(D6=A6,I6,"") | H6: Add to table | K6: =IF(A6=B6,N6,"") | L6: =IF(C6=A6,N6,"") | M6: =IF(D6=A6,N6,"")
A7: 6 | B7: =B6 -> 2 | C7: =C6 -> 1 | D7: =D6 -> 1 | E7: =IF(B7=A7,I7,"") | F7: =IF(C7=A7,I7,"") | G7: =IF(D7=A7,I7,"") | H7: Add to table | K7: =IF(A7=B7,N7,"") | L7: =IF(C7=A7,N7,"") | M7: =IF(D7=A7,N7,"")
A8: 7 | B8: =B7 -> 2 | C8: =C7 -> 1 | D8: =D7 -> 1 | E8: =IF(B8=A8,I8,"") | F8: =IF(C8=A8,I8,"") | G8: =IF(D8=A8,I8,"") | H8: Add to table | K8: =IF(A8=B8,N8,"") | L8: =IF(C8=A8,N8,"") | M8: =IF(D8=A8,N8,"")
A9: 8 | B9: =B8 -> 2 | C9: =C8 -> 1 | D9: =D8 -> 1 | E9: =IF(B9=A9,I9,"") | F9: =IF(C9=A9,I9,"") | G9: =IF(D9=A9,I9,"") | H9: Add to table | K9: =IF(A9=B9,N9,"") | L9: =IF(C9=A9,N9,"") | M9: =IF(D9=A9,N9,"")
A10: 9 | B10: =B9 -> 2 | C10: =C9 -> 1 | D10: =D9 -> 1 | E10: =IF(B10=A10,I10,"") | F10: =IF(C10=A10,I10,"") | G10: =IF(D10=A10,I10,"") | H10: Add to table | K10: =IF(A10=B10,N10,"") | L10: =IF(C10=A10,N10,"") | M10: =IF(D10=A10,N10,"")
A11: 10 | B11: =B10 -> 2 | C11: =C10 -> 1 | D11: =D10 -> 1 | E11: =IF(B11=A11,I11,"") | F11: =IF(C11=A11,I11,"") | G11: =IF(D11=A11,I11,"") | H11: Add to table | K11: =IF(A11=B11,N11,"") | L11: =IF(C11=A11,N11,"") | M11: =IF(D11=A11,N11,"")
A12: 11 | B12: =B11 -> 2 | C12: =C11 -> 1 | D12: =D11 -> 1 | E12: =IF(B12=A12,I12,"") | F12: =IF(C12=A12,I12,"") | G12: =IF(D12=A12,I12,"") | H12: Add to table | K12: =IF(A12=B12,N12,"") | L12: =IF(C12=A12,N12,"") | M12: =IF(D12=A12,N12,"")
A13: 12 | B13: =B12 -> 2 | C13: =C12 -> 1 | D13: =D12 -> 1 | E13: =IF(B13=A13,I13,"") | F13: =IF(C13=A13,I13,"") | G13: =IF(D13=A13,I13,"") | H13: Add to table | K13: =IF(A13=B13,N13,"") | L13: =IF(C13=A13,N13,"") | M13: =IF(D13=A13,N13,"")
A14: 13 | B14: =B13 -> 2 | C14: =C13 -> 1 | D14: =D13 -> 1 | E14: =IF(B14=A14,I14,"") | F14: =IF(C14=A14,I14,"") | G14: =IF(D14=A14,I14,"") | H14: Add to table | K14: =IF(A14=B14,N14,"") | L14: =IF(C14=A14,N14,"") | M14: =IF(D14=A14,N14,"")
A15: 14 | B15: =B14 -> 2 | C15: =C14 -> 1 | D15: =D14 -> 1 | E15: =IF(B15=A15,I15,"") | F15: =IF(C15=A15,I15,"") | G15: =IF(D15=A15,I15,"") | H15: Add to table | K15: =IF(A15=B15,N15,"") | L15: =IF(C15=A15,N15,"") | M15: =IF(D15=A15,N15,"")
A16: 15 | B16: =B15 -> 2 | C16: =C15 -> 1 | D16: =D15 -> 1 | E16: =IF(B16=A16,I16,"") | F16: =IF(C16=A16,I16,"") | G16: =IF(D16=A16,I16,"") | H16: Add to table | K16: =IF(A16=B16,N16,"") | L16: =IF(C16=A16,N16,"") | M16: =IF(D16=A16,N16,"")
A17: 16 | B17: =B16 -> 2 | C17: =C16 -> 1 | D17: =D16 -> 1 | E17: =IF(B17=A17,I17,"") | F17: =IF(C17=A17,I17,"") | G17: =IF(D17=A17,I17,"") | H17: Add to table | K17: =IF(A17=B17,N17,"") | L17: =IF(C17=A17,N17,"") | M17: =IF(D17=A17,N17,"")
... A21: 20 | B21: =B20 -> 2 | C21: =C20 -> 1 | D21: =D20 -> 1 | E21: =IF(B21=A21,I21,"") | F21: =IF(C21=A21,I21,"") | G21: =IF(D21=A21,I21,"") | H21: Add to table | K21: =IF(A21=B21,N21,"") | L21: =IF(C21=A21,N21,"") | M21: =IF(D21=A21,N21,"")
E23: =SUM(E2:E21) -> 2705 | F23: =SUM(F2:F21) -> 2840 | G23: =SUM(G2:G21) -> 2840 | K23: =SUM(K2:K21) -> 575 | L23: =SUM(L2:L21) -> 150 | M23: =SUM(M2:M21) -> 150

Sheet Basic Calcs
A1: Dimensions
C2: Units | D2: Version 1 | E2: Version 2 | F2: Version 3 | G2: ISS | H2: Notes / Source | I2: Source
A3: Outer Diameter | B3: D1 | C3: m | D3: 100 | E3: 1000 | F3: 100000 | G3: 73 | H3: Inside diameter of the Seed Ring. ISS dimension relates to maximum length | I3: https://en.wikipedia.org/wiki/Electrical_system_of_the_International_Space_Station
A4: Section Outer Diameter | B4: d1 | C4: m | D4: 10 | E4: 100 | F4: 10000 | H4: Outside diamter of the section - for the purposes of simplicity assumed to be circular
A5: Inner Diameter | B5: D2 | C5: m | D5: =SUM(D3-(2*D4)) -> 80 | E5: =SUM(E3-(2*E4)) -> 800 | F5: =SUM(F3-(2*F4)) -> 80000
A6: Wall Thickness | B6: l1 | C6: m | D6: 0.05 | E6: 0.2 | F6: 1
A7: Outer Torus Volume | B7: V1 | C7: m3 | D7: =SUM(3.1416*3.1416)*(D3/2+D5/2)*(D3/2-D5/2)*(D3/2-D5/2)/4 -> 22206.714 | E7: =SUM(3.1416*3.1416)*(E3/2+E5/2)*(E3/2-E5/2)*(E3/2-E5/2)/4 -> 22206714 | F7: =SUM(3.1416*3.1416)*(F3/2+F5/2)*(F3/2-F5/2)*(F3/2-F5/2)/4 -> 22206713760000
A8: Inside Torus Outer Diameter | C8: m | D8: =D3-(D6*2) -> 99.9 | E8: =E3-(E6*2) -> 999.6 | F8: =F3-(F6*2) -> 99998
A9: Inside Torus Inner Diameter | C9: m | D9: =D5+(D6*2) -> 80.1 | E9: =E5+(E6*2) -> 800.4 | F9: =F5+(F6*2) -> 80002
A10: Inside Torus Volume | C10: m3 | D10: =SUM(3.1416*3.1416)*(D8/2+D9/2)*(D8/2-D9/2)*(D8/2-D9/2)/4 -> 21764.8 | E10: =SUM(3.1416*3.1416)*(E8/2+E9/2)*(E8/2-E9/2)*(E8/2-E9/2)/4 -> 22029415 | F10: =SUM(3.1416*3.1416)*(F8/2+F9/2)*(F8/2-F9/2)*(F8/2-F9/2)/4 -> 2.2197832e+13 | H10: Layer thickness
A11: Torus Shell Volume | C11: m3 | D11: =SUM(D7-D10) -> 441.9136 | E11: =SUM(E7-E10) -> 177298.4 | F11: =SUM(F7-F10) -> 8.8817972e+09
A12: Central floor Volume | C12: m3 | D12: =(3.1416*D6*D8*(D4-2*D6)) -> 155.35369 | E12: =(3.1416*E6/4*(E8*E8-(E9*E9))) -> 56322.605 | F12: =(3.1416*F6/4*(F8*F8-(F9*F9))) -> 2826874512 | H12: Volume associated with a ring shaped floor at the widest point wih a thickness equal to the outer wall
A13: Additional Print Volume | C13: % | D13: 4 | E13: 5 | F13: 6 | H13: For further inner floors / walls as a percentage of the central floor volume
A14: Additional Print Volume | C14: m3 | D14: =SUM(D13*D12)+D12 -> 776.76845 | E14: =SUM(E13*E12)+E12 -> 337935.63 | F14: =SUM(F13*F12)+F12 -> 19788121584
A15: Internal Volume | C15: m3 | D15: =D10-D14 -> 20988.032 | E15: =E10-E14 -> 21691480 | F15: =F10-F14 -> 2.2178044e+13 | G15: 932 | I15: https://www.nasa.gov/feature/facts-and-figures
A16: Total Print Volume | C16: m3 | D16: =D11+D14 -> 1218.6821 | E16: =E11+E14 -> 515234.03 | F16: =F11+F14 -> 2.8669919e+10
A17: People on Board | D17: 50 | E17: 100000 | F17: 50000000 | G17: 6
A18: Average volume per person | C18: m3 | D18: =D15/D17 -> 419.76063 | E18: =E15/E17 -> 216.9148 | F18: =F15/F17 -> 443560.88 | G18: =SUM(G15/G17) -> 155.33333
A20: Materials
A22: Main Structure Material
A23: Material Density | C23: kg/m3 | D23: ='Materials Table'!E23 -> 2705 | E23: ='Materials Table'!F23 -> 2840 | F23: ='Materials Table'!G23 -> 2840 | H23: From Table
A24: Wall Design Density | C24: % | D24: 0.75 | E24: 0.75 | F24: 0.75
A25: Total Mass | C25: Tonnes | D25: =SUM(D16)*D23/1000*D24 -> 2472.4012 | E25: =SUM(E16)*E23/1000*E24 -> 1097448.5 | F25: =SUM(F16)*F23/1000*F24 -> 6.1066927e+10 | G25: 420 | I25: https://www.nasa.gov/feature/facts-and-figures
A26: Falcon Heavy Lifts | D26: =SUM(D25/64) -> 38.631269 | E26: =SUM(E25/64) -> 17147.633 | F26: =SUM(F25/64) -> 9.5417074e+08 | H26: 64 Ton lift capacity
A27: Lifts frequency | C27: days | D27: =SUM(365/(D26/D42)) -> 25.355677 | E27: =SUM(365/(E26/E42)) -> 0.096601557 | F27: =SUM(365/(F26/F42)) -> 3.8640623e-06
A29: Manufacturing Process
A31: Print Speed | C31: m/s | D31: 0.5 | E31: 1 | F31: 1 | H31: How fast the printer head moves relative to the surface being printed
A32: Nozzle Diameter | C32: mm | D32: 4 | E32: 100 | F32: 2000 | H32: Current home 3D print speed. Aluminium extrusion in range of 5 - 50 m/min (0.08 - 0.8 m/s)
A33: Print Depth | C33: mm | D33: 2 | E33: 10 | F33: 500
A34: Nozzle volumetric flow rate | C34: cm3/s | D34: =SUM(D32*D31*D33) -> 4 | E34: =SUM(E32*E31*E33) -> 1000 | F34: =SUM(F32*F31*F33) -> 1000000
A35: Rotational Speed | C35: RPM | D35: =D31/(3.1416*D3)*60 -> 0.095492743 | E35: =E31/(3.1416*E3)*60 -> 0.019098549 | F35: =F31/(3.1416*F3)*60 -> 0.00019098549 | H35: Calculated from the print head speed at the outer diameter
A36: G-force outer edge (RCF) | D36: =D35*D35*1.118*0.001*(D3/2) -> 0.00050974449 | E36: =E35*E35*1.118*0.001*(E3/2) -> 0.0002038978 | F36: =F35*F35*1.118*0.001*(F3/2) -> 2.038978e-06
A37: Number of Print Heads | D37: 4 | E37: 4 | F37: 100 | H37: Number of nozzles for the main construction material - separate print head are assumed for other materials
A38: Flow Rate per Nozzles | C38: kg/s | D38: =D39/D37 -> 0.01082 | E38: =E39/E37 -> 2.84 | F38: =F39/F37 -> 2840
A39: Flow Rate All Nozzles | C39: kg/s | D39: =SUM(D34*D23*D37)/1000000 -> 0.04328 | E39: =SUM(E34*E23*E37)/1000000 -> 11.36 | F39: =SUM(F34*F23*F37)/1000000 -> 284000
A40: Print Efficiency | C40: % | D40: 0.9 | E40: 0.9 | F40: 0.9 | H40: Tme Printing vs Time Not Printing NOT INCLUDING wall design desity
A41: Print Time | C41: days | D41: =SUM(D25/D39)*1000/D40/D24/60/60/24 -> 979.52197 | E41: =SUM(E25/E39)*1000/E40/E24/60/60/24 -> 1656.488 | F41: =SUM(F25/F39)*1000/F40/F24/60/60/24 -> 3686.9752
A42: Print Time | C42: years | D42: =SUM(D41)/365 -> 2.6836218 | E42: =SUM(E41)/365 -> 4.5383233 | F42: =SUM(F41)/365 -> 10.101302
A44: Power Requirements
A46: Melt Energy | C46: GJ/ton | D46: ='Materials Table'!K$23*3600/1000000 -> 2.07 | E46: ='Materials Table'!L$23*3600/1000000 -> 0.54 | F46: ='Materials Table'!M$23*3600/1000000 -> 0.54
...

Sheet Materials Table
E1: 1 | F1: 2 | G1: 3 | H1: Material | I1: Density kg/m3 | J1: Notes / Source | N1: Melt Energy kWhrs/ton | O1: Notes / Source
A2: 1 | B2: 2 | C2: 1 | D2: 1 | E2: =IF(B2=A2,I2,"") | F2: =IF(C2=A2,I2,"") -> 2840 | G2: =IF(D2=A2,I2,"") -> 2840 | H2: Moon Rock | I2: 2840 | J2: http://www.psrd.hawaii.edu/CosmoSparks/July12/Lunar-rock-densities.html | K2: =IF(A2=B2,N2,"") | L2: =IF(C2=A2,N2,"") -> 150 | M2: =IF(D2=A2,N2,"") -> 150 | N2: 150 | O2: Assumed to be that of substrate material. Estimate only
A3: 2 | B3: =B2 -> 2 | C3: =C2 -> 1 | D3: =D2 -> 1 | E3: =IF(B3=A3,I3,"") -> 2705 | F3: =IF(C3=A3,I3,"") | G3: =IF(D3=A3,I3,"") | H3: Auminium | I3: 2705 | J3: https://theengineeringmindset.com/density-of-metals/ | K3: =IF(A3=B3,N3,"") -> 575 | L3: =IF(C3=A3,N3,"") | M3: =IF(D3=A3,N3,"") | N3: 575 | O3: https://electroheatinduction.com/how-to-calculate-electricity-cost-for-melting-metal-in-induction-melting-furnace/
A4: 3 | B4: =B3 -> 2 | C4: =C3 -> 1 | D4: =D3 -> 1 | E4: =IF(B4=A4,I4,"") | F4: =IF(C4=A4,I4,"") | G4: =IF(D4=A4,I4,"") | H4: Steel | I4: 7850 | J4: https://theengineeringmindset.com/density-of-metals/ | K4: =IF(A4=B4,N4,"") | L4: =IF(C4=A4,N4,"") | M4: =IF(D4=A4,N4,"") | N4: 600 | O4: https://electroheatinduction.com/how-to-calculate-electricity-cost-for-melting-metal-in-induction-melting-furnace/
A5: 4 | B5: =B4 -> 2 | C5: =C4 -> 1 | D5: =D4 -> 1 | E5: =IF(B5=A5,I5,"") | F5: =IF(C5=A5,I5,"") | G5: =IF(D5=A5,I5,"") | H5: High Impact ABS | I5: 1100 | J5: https://omnexus.specialchem.com/polymer-properties/properties/density | K5: =IF(A5=B5,N5,"") | L5: =IF(C5=A5,N5,"") | M5: =IF(D5=A5,N5,"") | N5: =0.00029307*342*1000 -> 100.22994 | O5: https://www.ptonline.com/articles/injection-molding-#:~:text=A%20kilogram%20of%20a%20semi-crystalline%20resin%2C%20such%20as,vs.%20342%29%2C%20yet%20their%20processing%20temperatures%20are%20similar.
A6: 5 | B6: =B5 -> 2 | C6: =C5 -> 1 | D6: =D5 -> 1 | E6: =IF(B6=A6,I6,"") | F6: =IF(C6=A6,I6,"") | G6: =IF(D6=A6,I6,"") | H6: Add to table | K6: =IF(A6=B6,N6,"") | L6: =IF(C6=A6,N6,"") | M6: =IF(D6=A6,N6,"")
A7: 6 | B7: =B6 -> 2 | C7: =C6 -> 1 | D7: =D6 -> 1 | E7: =IF(B7=A7,I7,"") | F7: =IF(C7=A7,I7,"") | G7: =IF(D7=A7,I7,"") | H7: Add to table | K7: =IF(A7=B7,N7,"") | L7: =IF(C7=A7,N7,"") | M7: =IF(D7=A7,N7,"")
A8: 7 | B8: =B7 -> 2 | C8: =C7 -> 1 | D8: =D7 -> 1 | E8: =IF(B8=A8,I8,"") | F8: =IF(C8=A8,I8,"") | G8: =IF(D8=A8,I8,"") | H8: Add to table | K8: =IF(A8=B8,N8,"") | L8: =IF(C8=A8,N8,"") | M8: =IF(D8=A8,N8,"")
A9: 8 | B9: =B8 -> 2 | C9: =C8 -> 1 | D9: =D8 -> 1 | E9: =IF(B9=A9,I9,"") | F9: =IF(C9=A9,I9,"") | G9: =IF(D9=A9,I9,"") | H9: Add to table | K9: =IF(A9=B9,N9,"") | L9: =IF(C9=A9,N9,"") | M9: =IF(D9=A9,N9,"")
A10: 9 | B10: =B9 -> 2 | C10: =C9 -> 1 | D10: =D9 -> 1 | E10: =IF(B10=A10,I10,"") | F10: =IF(C10=A10,I10,"") | G10: =IF(D10=A10,I10,"") | H10: Add to table | K10: =IF(A10=B10,N10,"") | L10: =IF(C10=A10,N10,"") | M10: =IF(D10=A10,N10,"")
A11: 10 | B11: =B10 -> 2 | C11: =C10 -> 1 | D11: =D10 -> 1 | E11: =IF(B11=A11,I11,"") | F11: =IF(C11=A11,I11,"") | G11: =IF(D11=A11,I11,"") | H11: Add to table | K11: =IF(A11=B11,N11,"") | L11: =IF(C11=A11,N11,"") | M11: =IF(D11=A11,N11,"")
A12: 11 | B12: =B11 -> 2 | C12: =C11 -> 1 | D12: =D11 -> 1 | E12: =IF(B12=A12,I12,"") | F12: =IF(C12=A12,I12,"") | G12: =IF(D12=A12,I12,"") | H12: Add to table | K12: =IF(A12=B12,N12,"") | L12: =IF(C12=A12,N12,"") | M12: =IF(D12=A12,N12,"")
A13: 12 | B13: =B12 -> 2 | C13: =C12 -> 1 | D13: =D12 -> 1 | E13: =IF(B13=A13,I13,"") | F13: =IF(C13=A13,I13,"") | G13: =IF(D13=A13,I13,"") | H13: Add to table | K13: =IF(A13=B13,N13,"") | L13: =IF(C13=A13,N13,"") | M13: =IF(D13=A13,N13,"")
A14: 13 | B14: =B13 -> 2 | C14: =C13 -> 1 | D14: =D13 -> 1 | E14: =IF(B14=A14,I14,"") | F14: =IF(C14=A14,I14,"") | G14: =IF(D14=A14,I14,"") | H14: Add to table | K14: =IF(A14=B14,N14,"") | L14: =IF(C14=A14,N14,"") | M14: =IF(D14=A14,N14,"")
A15: 14 | B15: =B14 -> 2 | C15: =C14 -> 1 | D15: =D14 -> 1 | E15: =IF(B15=A15,I15,"") | F15: =IF(C15=A15,I15,"") | G15: =IF(D15=A15,I15,"") | H15: Add to table | K15: =IF(A15=B15,N15,"") | L15: =IF(C15=A15,N15,"") | M15: =IF(D15=A15,N15,"")
A16: 15 | B16: =B15 -> 2 | C16: =C15 -> 1 | D16: =D15 -> 1 | E16: =IF(B16=A16,I16,"") | F16: =IF(C16=A16,I16,"") | G16: =IF(D16=A16,I16,"") | H16: Add to table | K16: =IF(A16=B16,N16,"") | L16: =IF(C16=A16,N16,"") | M16: =IF(D16=A16,N16,"")
A17: 16 | B17: =B16 -> 2 | C17: =C16 -> 1 | D17: =D16 -> 1 | E17: =IF(B17=A17,I17,"") | F17: =IF(C17=A17,I17,"") | G17: =IF(D17=A17,I17,"") | H17: Add to table | K17: =IF(A17=B17,N17,"") | L17: =IF(C17=A17,N17,"") | M17: =IF(D17=A17,N17,"")
... A21: 20 | B21: =B20 -> 2 | C21: =C20 -> 1 | D21: =D20 -> 1 | E21: =IF(B21=A21,I21,"") | F21: =IF(C21=A21,I21,"") | G21: =IF(D21=A21,I21,"") | H21: Add to table | K21: =IF(A21=B21,N21,"") | L21: =IF(C21=A21,N21,"") | M21: =IF(D21=A21,N21,"")
E23: =SUM(E2:E21) -> 2705 | F23: =SUM(F2:F21) -> 2840 | G23: =SUM(G2:G21) -> 2840 | K23: =SUM(K2:K21) -> 575 | L23: =SUM(L2:L21) -> 150 | M23: =SUM(M2:M21) -> 150

Sheet Charts

Sheet Basic Calcs 100m
A2: Dimensions
C4: Units | D4: Option 1 | E4: Option 2 | F4: Option 3 | G4: ISS | H4: Notes | I4: Source
A5: Outer Diameter | B5: D1 | C5: m | D5: 100 | E5: 100 | F5: 100 | G5: 73 | H5: Inside diameter of the Seed Ring. ISS dimension relates to maximum length | I5: https://en.wikipedia.org/wiki/Electrical_system_of_the_International_Space_Station
A6: Section Outer Diameter | B6: d1 | C6: m | D6: 10 | E6: 10 | F6: 10 | H6: Outside diamter of the section - for the purposes of simplicity assumed to be circular
A7: Inner Diameter | B7: D2 | C7: m | D7: =SUM(D5-(2*D6)) -> 80 | E7: =SUM(E5-(2*E6)) -> 80 | F7: =SUM(F5-(2*F6)) -> 80
A8: Wall Thickness | B8: l1 | C8: m | D8: 0.02 | E8: 0.05 | F8: 0.1
A9: Section Area Outer | C9: m2 | D9: =SUM(3.1416/4*((D5*D5)-((D5-(2*D8))*(D5-(2*D8))))) -> 6.2819434 | E9: =SUM(3.1416/4*((E5*E5)-((E5-(2*E8))*(E5-(2*E8))))) -> 15.700146 | F9: =SUM(3.1416/4*((F5*F5)-((F5-(2*F8))*(F5-(2*F8))))) -> 31.384584 | H9: Area of the outer walls required to be fully covered by the print head
A10: Section Area Floor | C10: m2 | D10: =(D5-(D8*2))*D8 -> 1.9992 | E10: =(E5-(E8*2))*E8 -> 4.995 | F10: =(F5-(F8*2))*F8 -> 9.98 | H10: Area of the central floor area required to be fully covered by the print head
A11: Additional Print Area | C11: % | D11: 2 | E11: 2 | F11: 2 | H11: For further inner floors / walls as a percentage of the central floor section area
A12: Total Sectional Area | C12: m2 | D12: =D9+D10+(D10*D11) -> 12.279543 | E12: =E9+E10+(E10*E11) -> 30.685146 | F12: =F9+F10+(F10*F11) -> 61.324584 | H12: This number is used in conjunction with the print nozzle size and print depth to calculate how many revolutions are required to cover the area
A13: Outer Torus Volume | B13: V1 | C13: m3 | D13: =SUM(3.1416*3.1416)*(D5/2+D7/2)*(D5/2-D7/2)*(D5/2-D7/2)/4 -> 22206.714 | E13: =SUM(3.1416*3.1416)*(E5/2+E7/2)*(E5/2-E7/2)*(E5/2-E7/2)/4 -> 22206.714 | F13: =SUM(3.1416*3.1416)*(F5/2+F7/2)*(F5/2-F7/2)*(F5/2-F7/2)/4 -> 22206.714
A14: Inside Torus Outer Diameter | C14: m | D14: =D5-(D8*2) -> 99.96 | E14: =E5-(E8*2) -> 99.9 | F14: =F5-(F8*2) -> 99.8
A15: Inside Torus Inner Diameter | C15: m | D15: =D7+(D8*2) -> 80.04 | E15: =E7+(E8*2) -> 80.1 | F15: =F7+(F8*2) -> 80.2
A16: Inside Torus Volume | C16: m3 | D16: =SUM(3.1416*3.1416)*(D14/2+D15/2)*(D14/2-D15/2)*(D14/2-D15/2)/4 -> 22029.415 | E16: =SUM(3.1416*3.1416)*(E14/2+E15/2)*(E14/2-E15/2)*(E14/2-E15/2)/4 -> 21764.8 | F16: =SUM(3.1416*3.1416)*(F14/2+F15/2)*(F14/2-F15/2)*(F14/2-F15/2)/4 -> 21327.328 | H16: Layer thickness
A17: Torus Shell Volume | C17: m3 | D17: =SUM(D13-D16) -> 177.2984 | E17: =SUM(E13-E16) -> 441.9136 | F17: =SUM(F13-F16) -> 879.38586
A18: Central floor Volume | C18: m3 | D18: =(3.1416*D8*D14*(D6-2*D8)) -> 62.55564 | E18: =(3.1416*E8*E14*(E6-2*E8)) -> 155.35369 | F18: =(3.1416*F8*F14*(F6-2*F8)) -> 307.26105 | H18: Volume associated with a ring shaped floor at the widest point wih a thickness equal to the outer wall
A19: Additional Print Volume | C19: m3 | D19: =SUM(D11*D18)+D18 -> 187.66692 | E19: =SUM(E11*E18)+E18 -> 466.06107 | F19: =SUM(F11*F18)+F18 -> 921.78314
A20: Internal Volume | C20: m3 | D20: =D16-D19 -> 21841.748 | E20: =E16-E19 -> 21298.739 | F20: =F16-F19 -> 20405.545 | G20: 932 | I20: https://www.nasa.gov/feature/facts-and-figures
A21: Total Print Volume | C21: m3 | D21: =D17+D19 -> 364.96532 | E21: =E17+E19 -> 907.97468 | F21: =F17+F19 -> 1801.169
A22: People on Board | D22: 50 | E22: 50 | F22: 50 | G22: 6 | H22: Possibly constrained by bed space
A23: Average volume per person | C23: m3 | D23: =D20/D22 -> 436.83497 | E23: =E20/E22 -> 425.97478 | F23: =F20/F22 -> 408.1109 | G23: =SUM(G20/G22) -> 155.33333
A24: Floor Space per person at 2.5 m ceiling | C24: m2 | D24: =D23/2.5 -> 174.73399 | E24: =E23/2.5 -> 170.38991 | F24: =F23/2.5 -> 163.24436 | H24: Approximate calculation does not consider curvature of structure
A26: Manufacturing Process
A28: Print Speed | C28: m/s | D28: 0.5 | E28: 0.5 | F28: 1 | H28: How fast the printer head moves relative to the surface being printed Current home 3D print speed. Aluminium extrusion in range of 5 - 50 m/min (0.08 - 0.8 m/s)
A29: Nozzle Diameter | C29: mm | D29: 4 | E29: 4 | F29: 4
A30: Print Depth | C30: mm | D30: 2 | E30: 2 | F30: 2
A31: Nozzle volumetric flow rate | C31: cm3/s | D31: =SUM(D29*D28*D30) -> 4 | E31: =SUM(E29*E28*E30) -> 4 | F31: =SUM(F29*F28*F30) -> 8 | H31: For all Nozzles
A32: Rotational Speed | C32: RPM | D32: =D28*60/(3.1416*D5) -> 0.095492743 | E32: =E28*60/(3.1416*E5) -> 0.095492743 | F32: =F28*60/(3.1416*F5) -> 0.19098549 | H32: Calculated from the print head speed at the outer diameter
A33: G-force outer edge (RCF) | D33: =D32*D32*1.118*0.001*(D5/2) -> 0.00050974449 | E33: =E32*E32*1.118*0.001*(E5/2) -> 0.00050974449 | F33: =F32*F32*1.118*0.001*(F5/2) -> 0.002038978 | H33: Induced by rotation of ring
A34: Number of Print Head Nozzles | D34: 4 | E34: 16 | F34: 8 | H34: Number of nozzles for the main construction material - separate print head are assumed for other materials
A35: Flow Rate per Nozzles | C35: kg/s | D35: =D36/D34 -> 0.01082 | E35: =E36/E34 -> 0.01082 | F35: =F36/F34 -> 0.0088
A36: Flow Rate All Nozzles | C36: kg/s | D36: =SUM(D31*D45*D34)/1000000 -> 0.04328 | E36: =SUM(E31*E45*E34)/1000000 -> 0.17312 | F36: =SUM(F31*F45*F34)/1000000 -> 0.0704 | H36: Used in power sonsumption calculations
A37: Print Efficiency | C37: % | D37: 0.9 | E37: 0.9 | F37: 0.9 | H37: Tme Printing vs Time Not Printing NOT INCLUDING wall design desity
A38: Number of Complete Revolutions | C38: million | D38: =D12/(D29*D30*D34/1000000)/1000000 -> 0.38373573 | E38: =E12/(E29*E30*E34/1000000)/1000000 -> 0.2397277 | F38: =F12/(F29*F30*F34/1000000)/1000000 -> 0.95819663 | H38: Based upon the total sectional area divided by the print area (nozzle diameter x print depth x number of nozzles)
A39: Print Time | C39: days | D39: =((D38*1000000)/D32)/60/24/D37 -> 3100.6794 | E39: =((E38*1000)/E32)/60/24/E37*1000 -> 1937.059 | F39: =((F38*1000)/F32)/60/24/F37*1000 -> 3871.2327 | H39: Calculated using number of revolutions and rotaional speed
A40: Print Time | C40: years | D40: =SUM(D39)/365 -> 8.4950122 | E40: =SUM(E39)/365 -> 5.3070111 | F40: =SUM(F39)/365 -> 10.606117
A42: Material Requirements
A44: Main Structure Material
A45: Material Density | C45: kg/m3 | D45: ='Materials Table 100m'!E23 -> 2705 | E45: ='Materials Table 100m'!F23 -> 2705 | F45: ='Materials Table 100m'!G23 -> 1100 | H45: From Table
A46: Wall Design Density | C46: % | D46: 0.5 | E46: 0.5 | F46: 0.5
...

Sheet Charts 100m
B1: Version 1 | C1: Version 2 | D1: Version 3 | H1: Version 1 | I1: Version 2 | J1: Version 3
A2: Wall Thickness | B2: ='Basic Calcs 100m'!D8*100 -> 2 | C2: ='Basic Calcs 100m'!E8*100 -> 5 | D2: ='Basic Calcs 100m'!F8*100 -> 10 | E2: cm | G2: Wall Thickness | H2: 2 | I2: 5 | J2: 10
A3: Print Time | B3: ='Basic Calcs 100m'!D40 -> 8.4950122 | C3: ='Basic Calcs 100m'!E40 -> 5.3070111 | D3: ='Basic Calcs 100m'!F40 -> 10.606117 | E3: years | G3: Print Time | H3: 1.0791824 | I3: 2.6836218 | J3: 5.3195182
A5: Wall Thickness | B5: =B2 -> 2 | C5: =C2 -> 5 | D5: =D2 -> 10
A6: Falcon Heavy Lifts | B6: ='Basic Calcs 100m'!D49 -> 7.7127437 | C6: ='Basic Calcs 100m'!E49 -> 19.188059 | D6: ='Basic Calcs 100m'!F49 -> 15.478796
A8: Total Print Volume | B8: ='Basic Calcs 100m'!D21 -> 364.96532 | C8: ='Basic Calcs 100m'!E21 -> 907.97468 | D8: ='Basic Calcs 100m'!F21 -> 1801.169 | E8: m3
A9: People on Board | B9: ='Basic Calcs 100m'!D22 -> 50 | C9: ='Basic Calcs 100m'!E22 -> 50 | D9: ='Basic Calcs 100m'!F22 -> 50
A10: Average volume per person | B10: ='Basic Calcs 100m'!D23 -> 436.83497 | C10: ='Basic Calcs 100m'!E23 -> 425.97478 | D10: ='Basic Calcs 100m'!F23 -> 408.1109 | E10: m3
A11: Total Mass | B11: ='Basic Calcs 100m'!D47 -> 493.6156 | C11: ='Basic Calcs 100m'!E47 -> 1228.0357 | D11: ='Basic Calcs 100m'!F47 -> 990.64295 | E11: Tonnes
A13: Lifts frequency | B13: ='Basic Calcs 100m'!D51 -> 402.02029 | C13: ='Basic Calcs 100m'!E51 -> 100.95128 | D13: ='Basic Calcs 100m'!F51 -> 250.09908 | E13: days
A15: Continuous Power | B15: ='Basic Calcs 100m'!D59 -> 127.98514 | C15: ='Basic Calcs 100m'!E59 -> 511.94057 | D15: ='Basic Calcs 100m'!F59 -> 36.288966 | E15: kW
A16: Theroretical Minimum Panel Size | B16: ='Basic Calcs 100m'!D62 -> 312.54003 | C16: ='Basic Calcs 100m'!E62 -> 1250.1601 | D16: ='Basic Calcs 100m'!F62 -> 88.617743 | E16: m2

Sheet Materials Table 100m
E1: 1 | F1: 2 | G1: 3 | H1: Material | I1: Density kg/m3 | J1: Notes / Source | N1: Melt Energy kWhrs/ton | O1: Notes / Source
A2: 1 | B2: 2 | C2: 2 | D2: 4 | E2: =IF(B2=A2,I2,"") | F2: =IF(C2=A2,I2,"") | G2: =IF(D2=A2,I2,"") | H2: ='Materials Properties'!H2 -> Moon Rock | I2: ='Materials Properties'!I2 -> 2840 | J2: http://www.psrd.hawaii.edu/CosmoSparks/July12/Lunar-rock-densities.html | K2: =IF(A2=B2,N2,"") | L2: =IF(C2=A2,N2,"") | M2: =IF(D2=A2,N2,"") | N2: ='Materials Properties'!N2 -> 150 | O2: Assumed to be that of substrate material. Estimate only
A3: 2 | B3: =B2 -> 2 | C3: =C2 -> 2 | D3: =D2 -> 4 | E3: =IF(B3=A3,I3,"") -> 2705 | F3: =IF(C3=A3,I3,"") -> 2705 | G3: =IF(D3=A3,I3,"") | H3: ='Materials Properties'!H3 -> Auminium | I3: ='Materials Properties'!I3 -> 2705 | J3: https://theengineeringmindset.com/density-of-metals/ | K3: =IF(A3=B3,N3,"") -> 575 | L3: =IF(C3=A3,N3,"") -> 575 | M3: =IF(D3=A3,N3,"") | N3: ='Materials Properties'!N3 -> 575 | O3: https://electroheatinduction.com/how-to-calculate-electricity-cost-for-melting-metal-in-induction-melting-furnace/
A4: 3 | B4: =B3 -> 2 | C4: =C3 -> 2 | D4: =D3 -> 4 | E4: =IF(B4=A4,I4,"") | F4: =IF(C4=A4,I4,"") | G4: =IF(D4=A4,I4,"") | H4: ='Materials Properties'!H4 -> Steel | I4: ='Materials Properties'!I4 -> 7850 | J4: https://theengineeringmindset.com/density-of-metals/ | K4: =IF(A4=B4,N4,"") | L4: =IF(C4=A4,N4,"") | M4: =IF(D4=A4,N4,"") | N4: ='Materials Properties'!N4 -> 600 | O4: https://electroheatinduction.com/how-to-calculate-electricity-cost-for-melting-metal-in-induction-melting-furnace/
A5: 4 | B5: =B4 -> 2 | C5: =C4 -> 2 | D5: =D4 -> 4 | E5: =IF(B5=A5,I5,"") | F5: =IF(C5=A5,I5,"") | G5: =IF(D5=A5,I5,"") -> 1100 | H5: ='Materials Properties'!H5 -> High Impact ABS | I5: ='Materials Properties'!I5 -> 1100 | J5: https://omnexus.specialchem.com/polymer-properties/properties/density | K5: =IF(A5=B5,N5,"") | L5: =IF(C5=A5,N5,"") | M5: =IF(D5=A5,N5,"") -> 100.22994 | N5: ='Materials Properties'!N5 -> 100.22994 | O5: https://www.ptonline.com/articles/injection-molding-#:~:text=A%20kilogram%20of%20a%20semi-crystalline%20resin%2C%20such%20as,vs.%20342%29%2C%20yet%20their%20processing%20temperatures%20are%20similar.
A6: 5 | B6: =B5 -> 2 | C6: =C5 -> 2 | D6: =D5 -> 4 | E6: =IF(B6=A6,I6,"") | F6: =IF(C6=A6,I6,"") | G6: =IF(D6=A6,I6,"") | H6: ='Materials Properties'!H6 -> Add to table | I6: ='Materials Properties'!I6 -> 0 | K6: =IF(A6=B6,N6,"") | L6: =IF(C6=A6,N6,"") | M6: =IF(D6=A6,N6,"") | N6: ='Materials Properties'!N6 -> 0
A7: 6 | B7: =B6 -> 2 | C7: =C6 -> 2 | D7: =D6 -> 4 | E7: =IF(B7=A7,I7,"") | F7: =IF(C7=A7,I7,"") | G7: =IF(D7=A7,I7,"") | H7: ='Materials Properties'!H7 -> Add to table | I7: ='Materials Properties'!I7 -> 0 | K7: =IF(A7=B7,N7,"") | L7: =IF(C7=A7,N7,"") | M7: =IF(D7=A7,N7,"") | N7: ='Materials Properties'!N7 -> 0
A8: 7 | B8: =B7 -> 2 | C8: =C7 -> 2 | D8: =D7 -> 4 | E8: =IF(B8=A8,I8,"") | F8: =IF(C8=A8,I8,"") | G8: =IF(D8=A8,I8,"") | H8: ='Materials Properties'!H8 -> Add to table | I8: ='Materials Properties'!I8 -> 0 | K8: =IF(A8=B8,N8,"") | L8: =IF(C8=A8,N8,"") | M8: =IF(D8=A8,N8,"") | N8: ='Materials Properties'!N8 -> 0
A9: 8 | B9: =B8 -> 2 | C9: =C8 -> 2 | D9: =D8 -> 4 | E9: =IF(B9=A9,I9,"") | F9: =IF(C9=A9,I9,"") | G9: =IF(D9=A9,I9,"") | H9: ='Materials Properties'!H9 -> Add to table | I9: ='Materials Properties'!I9 -> 0 | K9: =IF(A9=B9,N9,"") | L9: =IF(C9=A9,N9,"") | M9: =IF(D9=A9,N9,"") | N9: ='Materials Properties'!N9 -> 0
A10: 9 | B10: =B9 -> 2 | C10: =C9 -> 2 | D10: =D9 -> 4 | E10: =IF(B10=A10,I10,"") | F10: =IF(C10=A10,I10,"") | G10: =IF(D10=A10,I10,"") | H10: ='Materials Properties'!H10 -> Add to table | I10: ='Materials Properties'!I10 -> 0 | K10: =IF(A10=B10,N10,"") | L10: =IF(C10=A10,N10,"") | M10: =IF(D10=A10,N10,"") | N10: ='Materials Properties'!N10 -> 0
A11: 10 | B11: =B10 -> 2 | C11: =C10 -> 2 | D11: =D10 -> 4 | E11: =IF(B11=A11,I11,"") | F11: =IF(C11=A11,I11,"") | G11: =IF(D11=A11,I11,"") | H11: ='Materials Properties'!H11 -> Add to table | I11: ='Materials Properties'!I11 -> 0 | K11: =IF(A11=B11,N11,"") | L11: =IF(C11=A11,N11,"") | M11: =IF(D11=A11,N11,"") | N11: ='Materials Properties'!N11 -> 0
A12: 11 | B12: =B11 -> 2 | C12: =C11 -> 2 | D12: =D11 -> 4 | E12: =IF(B12=A12,I12,"") | F12: =IF(C12=A12,I12,"") | G12: =IF(D12=A12,I12,"") | H12: ='Materials Properties'!H12 -> Add to table | I12: ='Materials Properties'!I12 -> 0 | K12: =IF(A12=B12,N12,"") | L12: =IF(C12=A12,N12,"") | M12: =IF(D12=A12,N12,"") | N12: ='Materials Properties'!N12 -> 0
A13: 12 | B13: =B12 -> 2 | C13: =C12 -> 2 | D13: =D12 -> 4 | E13: =IF(B13=A13,I13,"") | F13: =IF(C13=A13,I13,"") | G13: =IF(D13=A13,I13,"") | H13: ='Materials Properties'!H13 -> Add to table | I13: ='Materials Properties'!I13 -> 0 | K13: =IF(A13=B13,N13,"") | L13: =IF(C13=A13,N13,"") | M13: =IF(D13=A13,N13,"") | N13: ='Materials Properties'!N13 -> 0
A14: 13 | B14: =B13 -> 2 | C14: =C13 -> 2 | D14: =D13 -> 4 | E14: =IF(B14=A14,I14,"") | F14: =IF(C14=A14,I14,"") | G14: =IF(D14=A14,I14,"") | H14: ='Materials Properties'!H14 -> Add to table | I14: ='Materials Properties'!I14 -> 0 | K14: =IF(A14=B14,N14,"") | L14: =IF(C14=A14,N14,"") | M14: =IF(D14=A14,N14,"") | N14: ='Materials Properties'!N14 -> 0
A15: 14 | B15: =B14 -> 2 | C15: =C14 -> 2 | D15: =D14 -> 4 | E15: =IF(B15=A15,I15,"") | F15: =IF(C15=A15,I15,"") | G15: =IF(D15=A15,I15,"") | H15: ='Materials Properties'!H15 -> Add to table | I15: ='Materials Properties'!I15 -> 0 | K15: =IF(A15=B15,N15,"") | L15: =IF(C15=A15,N15,"") | M15: =IF(D15=A15,N15,"") | N15: ='Materials Properties'!N15 -> 0
A16: 15 | B16: =B15 -> 2 | C16: =C15 -> 2 | D16: =D15 -> 4 | E16: =IF(B16=A16,I16,"") | F16: =IF(C16=A16,I16,"") | G16: =IF(D16=A16,I16,"") | H16: ='Materials Properties'!H16 -> Add to table | I16: ='Materials Properties'!I16 -> 0 | K16: =IF(A16=B16,N16,"") | L16: =IF(C16=A16,N16,"") | M16: =IF(D16=A16,N16,"") | N16: ='Materials Properties'!N16 -> 0
A17: 16 | B17: =B16 -> 2 | C17: =C16 -> 2 | D17: =D16 -> 4 | E17: =IF(B17=A17,I17,"") | F17: =IF(C17=A17,I17,"") | G17: =IF(D17=A17,I17,"") | H17: ='Materials Properties'!H17 -> Add to table | I17: ='Materials Properties'!I17 -> 0 | K17: =IF(A17=B17,N17,"") | L17: =IF(C17=A17,N17,"") | M17: =IF(D17=A17,N17,"") | N17: ='Materials Properties'!N17 -> 0
... A21: 20 | B21: =B20 -> 2 | C21: =C20 -> 2 | D21: =D20 -> 4 | E21: =IF(B21=A21,I21,"") | F21: =IF(C21=A21,I21,"") | G21: =IF(D21=A21,I21,"") | H21: ='Materials Properties'!H21 -> Add to table | I21: ='Materials Properties'!I21 -> 0 | K21: =IF(A21=B21,N21,"") | L21: =IF(C21=A21,N21,"") | M21: =IF(D21=A21,N21,"") | N21: ='Materials Properties'!N21 -> 0
E23: =SUM(E2:E21) -> 2705 | F23: =SUM(F2:F21) -> 2705 | G23: =SUM(G2:G21) -> 1100 | K23: =SUM(K2:K21) -> 575 | L23: =SUM(L2:L21) -> 575 | M23: =SUM(M2:M21) -> 100.22994

Sheet Charts All
B1: Version 1 | C1: Version 2 | D1: Version 3 | H1: Version 1 | I1: Version 2 | J1: Version 3
A2: Wall Thickness | B2: ='Basic Calcs All'!D8*100 -> 2 | C2: ='Basic Calcs All'!E8*100 -> 50 | D2: ='Basic Calcs All'!F8*100 -> 1000 | E2: cm | G2: Wall Thickness | H2: 2 | I2: 5 | J2: 10
A3: Print Time | B3: ='Basic Calcs All'!D40 -> 8.4950122 | C3: ='Basic Calcs All'!E40 -> 7.1584713 | D3: ='Basic Calcs All'!F40 -> 2.291849 | E3: years | G3: Print Time | H3: 1.0791824 | I3: 2.6836218 | J3: 5.3195182
A5: Wall Thickness | B5: =B2 -> 2 | C5: =C2 -> 50 | D5: =D2 -> 1000
A6: Falcon Heavy Lifts | B6: ='Basic Calcs All'!D49 -> 7.7127437 | C6: ='Basic Calcs All'!E49 -> 40291.376 | D6: ='Basic Calcs All'!F49 -> 3.0484756e+10
A8: Total Print Volume | B8: ='Basic Calcs All'!D21 -> 364.96532 | C8: ='Basic Calcs All'!E21 -> 907974.68 | D8: ='Basic Calcs All'!F21 -> 1.3739608e+12 | E8: m3
A9: People on Board | B9: ='Basic Calcs All'!D22 -> 50 | C9: ='Basic Calcs All'!E22 -> 10000 | D9: ='Basic Calcs All'!F22 -> 100000000
A10: Average volume per person | B10: ='Basic Calcs All'!D23 -> 436.83497 | C10: ='Basic Calcs All'!E23 -> 2129.8739 | D10: ='Basic Calcs All'!F23 -> 208327.53 | E10: m3
A11: Total Mass | B11: ='Basic Calcs All'!D47 -> 493.6156 | C11: ='Basic Calcs All'!E47 -> 2578648.1 | D11: ='Basic Calcs All'!F47 -> 1.9510244e+12 | E11: Tonnes
A13: Lifts frequency | B13: ='Basic Calcs All'!D51 -> 402.02029 | C13: ='Basic Calcs All'!E51 -> 0.064848667 | D13: ='Basic Calcs All'!F51 -> 2.7440761e-08 | E13: days
A15: Continuous Power | B15: ='Basic Calcs All'!D59 -> 127.98514 | C15: ='Basic Calcs All'!E59 -> 70107.429 | D15: ='Basic Calcs All'!F59 -> 4.3817143e+10 | E15: kW
A16: Theroretical Minimum Panel Size | B16: ='Basic Calcs All'!D62 -> 312.54003 | C16: ='Basic Calcs All'!E62 -> 171202.51 | D16: ='Basic Calcs All'!F62 -> 1.0700157e+11 | E16: m2

Sheet Materials Table All
E1: 1 | F1: 2 | G1: 3 | H1: Material | I1: Density kg/m3 | J1: Notes / Source | N1: Melt Energy kWhrs/ton | O1: Notes / Source
A2: 1 | B2: 2 | C2: 1 | D2: 1 | E2: =IF(B2=A2,I2,"") | F2: =IF(C2=A2,I2,"") -> 2840 | G2: =IF(D2=A2,I2,"") -> 2840 | H2: Moon Rock | I2: 2840 | J2: http://www.psrd.hawaii.edu/CosmoSparks/July12/Lunar-rock-densities.html | K2: =IF(A2=B2,N2,"") | L2: =IF(C2=A2,N2,"") -> 150 | M2: =IF(D2=A2,N2,"") -> 150 | N2: 150 | O2: Assumed to be that of substrate material. Estimate only
A3: 2 | B3: =B2 -> 2 | C3: =C2 -> 1 | D3: =D2 -> 1 | E3: =IF(B3=A3,I3,"") -> 2705 | F3: =IF(C3=A3,I3,"") | G3: =IF(D3=A3,I3,"") | H3: Auminium | I3: 2705 | J3: https://theengineeringmindset.com/density-of-metals/ | K3: =IF(A3=B3,N3,"") -> 575 | L3: =IF(C3=A3,N3,"") | M3: =IF(D3=A3,N3,"") | N3: 575 | O3: https://electroheatinduction.com/how-to-calculate-electricity-cost-for-melting-metal-in-induction-melting-furnace/
A4: 3 | B4: =B3 -> 2 | C4: =C3 -> 1 | D4: =D3 -> 1 | E4: =IF(B4=A4,I4,"") | F4: =IF(C4=A4,I4,"") | G4: =IF(D4=A4,I4,"") | H4: Steel | I4: 7850 | J4: https://theengineeringmindset.com/density-of-metals/ | K4: =IF(A4=B4,N4,"") | L4: =IF(C4=A4,N4,"") | M4: =IF(D4=A4,N4,"") | N4: 600 | O4: https://electroheatinduction.com/how-to-calculate-electricity-cost-for-melting-metal-in-induction-melting-furnace/
A5: 4 | B5: =B4 -> 2 | C5: =C4 -> 1 | D5: =D4 -> 1 | E5: =IF(B5=A5,I5,"") | F5: =IF(C5=A5,I5,"") | G5: =IF(D5=A5,I5,"") | H5: High Impact ABS | I5: 1100 | J5: https://omnexus.specialchem.com/polymer-properties/properties/density | K5: =IF(A5=B5,N5,"") | L5: =IF(C5=A5,N5,"") | M5: =IF(D5=A5,N5,"") | N5: =0.00029307*342*1000 -> 100.22994 | O5: https://www.ptonline.com/articles/injection-molding-#:~:text=A%20kilogram%20of%20a%20semi-crystalline%20resin%2C%20such%20as,vs.%20342%29%2C%20yet%20their%20processing%20temperatures%20are%20similar.
A6: 5 | B6: =B5 -> 2 | C6: =C5 -> 1 | D6: =D5 -> 1 | E6: =IF(B6=A6,I6,"") | F6: =IF(C6=A6,I6,"") | G6: =IF(D6=A6,I6,"") | H6: Add to table | K6: =IF(A6=B6,N6,"") | L6: =IF(C6=A6,N6,"") | M6: =IF(D6=A6,N6,"")
A7: 6 | B7: =B6 -> 2 | C7: =C6 -> 1 | D7: =D6 -> 1 | E7: =IF(B7=A7,I7,"") | F7: =IF(C7=A7,I7,"") | G7: =IF(D7=A7,I7,"") | H7: Add to table | K7: =IF(A7=B7,N7,"") | L7: =IF(C7=A7,N7,"") | M7: =IF(D7=A7,N7,"")
A8: 7 | B8: =B7 -> 2 | C8: =C7 -> 1 | D8: =D7 -> 1 | E8: =IF(B8=A8,I8,"") | F8: =IF(C8=A8,I8,"") | G8: =IF(D8=A8,I8,"") | H8: Add to table | K8: =IF(A8=B8,N8,"") | L8: =IF(C8=A8,N8,"") | M8: =IF(D8=A8,N8,"")
A9: 8 | B9: =B8 -> 2 | C9: =C8 -> 1 | D9: =D8 -> 1 | E9: =IF(B9=A9,I9,"") | F9: =IF(C9=A9,I9,"") | G9: =IF(D9=A9,I9,"") | H9: Add to table | K9: =IF(A9=B9,N9,"") | L9: =IF(C9=A9,N9,"") | M9: =IF(D9=A9,N9,"")
A10: 9 | B10: =B9 -> 2 | C10: =C9 -> 1 | D10: =D9 -> 1 | E10: =IF(B10=A10,I10,"") | F10: =IF(C10=A10,I10,"") | G10: =IF(D10=A10,I10,"") | H10: Add to table | K10: =IF(A10=B10,N10,"") | L10: =IF(C10=A10,N10,"") | M10: =IF(D10=A10,N10,"")
A11: 10 | B11: =B10 -> 2 | C11: =C10 -> 1 | D11: =D10 -> 1 | E11: =IF(B11=A11,I11,"") | F11: =IF(C11=A11,I11,"") | G11: =IF(D11=A11,I11,"") | H11: Add to table | K11: =IF(A11=B11,N11,"") | L11: =IF(C11=A11,N11,"") | M11: =IF(D11=A11,N11,"")
A12: 11 | B12: =B11 -> 2 | C12: =C11 -> 1 | D12: =D11 -> 1 | E12: =IF(B12=A12,I12,"") | F12: =IF(C12=A12,I12,"") | G12: =IF(D12=A12,I12,"") | H12: Add to table | K12: =IF(A12=B12,N12,"") | L12: =IF(C12=A12,N12,"") | M12: =IF(D12=A12,N12,"")
A13: 12 | B13: =B12 -> 2 | C13: =C12 -> 1 | D13: =D12 -> 1 | E13: =IF(B13=A13,I13,"") | F13: =IF(C13=A13,I13,"") | G13: =IF(D13=A13,I13,"") | H13: Add to table | K13: =IF(A13=B13,N13,"") | L13: =IF(C13=A13,N13,"") | M13: =IF(D13=A13,N13,"")
A14: 13 | B14: =B13 -> 2 | C14: =C13 -> 1 | D14: =D13 -> 1 | E14: =IF(B14=A14,I14,"") | F14: =IF(C14=A14,I14,"") | G14: =IF(D14=A14,I14,"") | H14: Add to table | K14: =IF(A14=B14,N14,"") | L14: =IF(C14=A14,N14,"") | M14: =IF(D14=A14,N14,"")
A15: 14 | B15: =B14 -> 2 | C15: =C14 -> 1 | D15: =D14 -> 1 | E15: =IF(B15=A15,I15,"") | F15: =IF(C15=A15,I15,"") | G15: =IF(D15=A15,I15,"") | H15: Add to table | K15: =IF(A15=B15,N15,"") | L15: =IF(C15=A15,N15,"") | M15: =IF(D15=A15,N15,"")
A16: 15 | B16: =B15 -> 2 | C16: =C15 -> 1 | D16: =D15 -> 1 | E16: =IF(B16=A16,I16,"") | F16: =IF(C16=A16,I16,"") | G16: =IF(D16=A16,I16,"") | H16: Add to table | K16: =IF(A16=B16,N16,"") | L16: =IF(C16=A16,N16,"") | M16: =IF(D16=A16,N16,"")
A17: 16 | B17: =B16 -> 2 | C17: =C16 -> 1 | D17: =D16 -> 1 | E17: =IF(B17=A17,I17,"") | F17: =IF(C17=A17,I17,"") | G17: =IF(D17=A17,I17,"") | H17: Add to table | K17: =IF(A17=B17,N17,"") | L17: =IF(C17=A17,N17,"") | M17: =IF(D17=A17,N17,"")
... A21: 20 | B21: =B20 -> 2 | C21: =C20 -> 1 | D21: =D20 -> 1 | E21: =IF(B21=A21,I21,"") | F21: =IF(C21=A21,I21,"") | G21: =IF(D21=A21,I21,"") | H21: Add to table | K21: =IF(A21=B21,N21,"") | L21: =IF(C21=A21,N21,"") | M21: =IF(D21=A21,N21,"")
